Workbook

Sheet NTFP Check
A1: Resight ID | B1: Rankings | C1: Name | D1: Changes (Name, Title, Location, Picture)
A2: IND00327 | B2: Arbitration | C2: Indranil Deshmukh | D2: *Indranil D. Deshmukh*
A3: IND00345 | B3: Arbitration | C3: Lomesh Nidumuri | D3: *Lomesh Kiran Nidumuri*
A4: IND00788 | B4: Arbitration | C4: Shankh Sengupta | D4: *Partner & Head of Dispute Practice*
A5: IND01048 | B5: Arbitration | C5: Sneha Jaisingh | D5: *Partner and Practice Lead*
A6: IND07574 | B6: Arbitration | C6: Sooraj Sharma | D6: *Founding Partner*
A7: IND02631 | B7: Arbitration | C7: Gunita Pahwa | D7: *Delhi*
A8: IND02109 | B8: Capital Markets - Debt | C8: Uttara M. Kolhatkar | D8: *Uttara M. Kolhatkar*
A9: IND00398 | B9: Capital Markets - Debt; Private Capital | C9: Subhalakshmi Naskar | D9: *Partner (Co-head - Projects (Infrastructure))*
A10: IND00271 | B10: Capital Markets - Equity | C10: Abhinav Kumar | D10: *WRONG IMAGE - uses Abhinav Maker's*
A11: IND00715 | B11: Capital Markets - Equity | C11: Bhakta Patnaik | D11: Partner and Head of Capital Markets Practice
A12: IND00323 | B12: Capital Markets - Equity | C12: Gokul Rajan | D12: Regional *Co-*head
... A33: IND00250 | B33: International Trade | C33: Udayan Choksi | D33: *Senior Partner*

Sheet RISE_lawyers
A1: Resight ID | B1: Rankings | C1: Name | D1: Position | E1: Position Check | F1: Location | G1: Column1 | H1: Organisation | I1: Bio | J1: Changes (Name, Title, Location, Picture)
A2: IND00020 | B2: Arbitration | C2: Ajay Bhargava | D2: Partner | E2: =IF(D2=(_xlfn.XLOOKUP(RISE_lawyers!$A2, All!$A$2:$A$158,All!H$2:H$158)), TRUE, FALSE) -> TRUE | F2: Delhi | G2: =IF(F2=(_xlfn.XLOOKUP(RISE_lawyers!$A2, All!$A$2:$A$158,All!G$2:G$158)), TRUE, FALSE) -> TRUE | H2: Khaitan & Co | J2: X
A3: IND07515 | B3: Arbitration | C3: Ashim Sood | D3: Principal | E3: =IF(D3=(_xlfn.XLOOKUP(RISE_lawyers!$A3, All!$A$2:$A$158,All!H$2:H$158)), TRUE, FALSE) -> TRUE | F3: Delhi | G3: =IF(F3=(_xlfn.XLOOKUP(RISE_lawyers!$A3, All!$A$2:$A$158,All!G$2:G$158)), TRUE, FALSE) -> TRUE | H3: Ashim Sood Law Offices | J3: X
A4: IND00712 | B4: Arbitration | C4: Ashish Bhan | D4: Partner | E4: =IF(D4=(_xlfn.XLOOKUP(RISE_lawyers!$A4, All!$A$2:$A$158,All!H$2:H$158)), TRUE, FALSE) -> TRUE | F4: Delhi | G4: =IF(F4=(_xlfn.XLOOKUP(RISE_lawyers!$A4, All!$A$2:$A$158,All!G$2:G$158)), TRUE, FALSE) -> TRUE | H4: Trilegal | J4: X
A5: IND00439 | B5: Arbitration | C5: Binsy Susan | D5: Partner | E5: =IF(D5=(_xlfn.XLOOKUP(RISE_lawyers!$A5, All!$A$2:$A$158,All!H$2:H$158)), TRUE, FALSE) -> TRUE | F5: Delhi | G5: =IF(F5=(_xlfn.XLOOKUP(RISE_lawyers!$A5, All!$A$2:$A$158,All!G$2:G$158)), TRUE, FALSE) -> TRUE | H5: Shardul Amarchand Mangaldas & Co | J5: X
A6: IND00064 | B6: Arbitration | C6: Chakrapani Misra | D6: Senior Partner | E6: =IF(D6=(_xlfn.XLOOKUP(RISE_lawyers!$A6, All!$A$2:$A$158,All!H$2:H$158)), TRUE, FALSE) -> TRUE | F6: Mumbai | G6: =IF(F6=(_xlfn.XLOOKUP(RISE_lawyers!$A6, All!$A$2:$A$158,All!G$2:G$158)), TRUE, FALSE) -> TRUE | H6: Khaitan & Co | J6: X
A7: IND01936 | B7: Arbitration | C7: Dheeraj Nair | D7: Partner | E7: =IF(D7=(_xlfn.XLOOKUP(RISE_lawyers!$A7, All!$A$2:$A$158,All!H$2:H$158)), TRUE, FALSE) -> TRUE | F7: Delhi | G7: =IF(F7=(_xlfn.XLOOKUP(RISE_lawyers!$A7, All!$A$2:$A$158,All!G$2:G$158)), TRUE, FALSE) -> TRUE | H7: JSA Advocates & Solicitors | J7: X
A8: IND00456 | B8: Arbitration | C8: Ila Kapoor | D8: Partner | E8: =IF(D8=(_xlfn.XLOOKUP(RISE_lawyers!$A8, All!$A$2:$A$158,All!H$2:H$158)), TRUE, FALSE) -> TRUE | F8: Delhi | G8: =IF(F8=(_xlfn.XLOOKUP(RISE_lawyers!$A8, All!$A$2:$A$158,All!G$2:G$158)), TRUE, FALSE) -> TRUE | H8: Shardul Amarchand Mangaldas & Co | J8: X
A9: IND00327 | B9: Arbitration | C9: Indranil Deshmukh | D9: Partner & Head of Disputes | E9: =IF(D9=(_xlfn.XLOOKUP(RISE_lawyers!$A9, All!$A$2:$A$158,All!H$2:H$158)), TRUE, FALSE) -> TRUE | F9: Mumbai | G9: =IF(F9=(_xlfn.XLOOKUP(RISE_lawyers!$A9, All!$A$2:$A$158,All!G$2:G$158)), TRUE, FALSE) -> TRUE | H9: Cyril Amarchand Mangaldas | J9: *Indranil D. Deshmukh*
A10: IND00337 | B10: Arbitration | C10: Kapil Arora | D10: Partner | E10: =IF(D10=(_xlfn.XLOOKUP(RISE_lawyers!$A10, All!$A$2:$A$158,All!H$2:H$158)), TRUE, FALSE) -> TRUE | F10: Delhi | G10: =IF(F10=(_xlfn.XLOOKUP(RISE_lawyers!$A10, All!$A$2:$A$158,All!G$2:G$158)), TRUE, FALSE) -> TRUE | H10: Cyril Amarchand Mangaldas | J10: X
A11: IND00739 | B11: Arbitration | C11: Ketan Gaur | D11: Partner | E11: =IF(D11=(_xlfn.XLOOKUP(RISE_lawyers!$A11, All!$A$2:$A$158,All!H$2:H$158)), TRUE, FALSE) -> TRUE | F11: Delhi | G11: =IF(F11=(_xlfn.XLOOKUP(RISE_lawyers!$A11, All!$A$2:$A$158,All!G$2:G$158)), TRUE, FALSE) -> TRUE | H11: Trilegal | J11: X
A12: IND00112 | B12: Arbitration | C12: Kingshuk Banerjee | D12: Partner | E12: =IF(D12=(_xlfn.XLOOKUP(RISE_lawyers!$A12, All!$A$2:$A$158,All!H$2:H$158)), TRUE, FALSE) -> TRUE | F12: Mumbai | G12: =IF(F12=(_xlfn.XLOOKUP(RISE_lawyers!$A12, All!$A$2:$A$158,All!G$2:G$158)), TRUE, FALSE) -> TRUE | H12: Khaitan & Co | J12: X
A13: IND00345 | B13: Arbitration | C13: Lomesh Nidumuri | D13: Partner (Head - Disputes, South India) | E13: =IF(D13=(_xlfn.XLOOKUP(RISE_lawyers!$A13, All!$A$2:$A$158,All!H$2:H$158)), TRUE, FALSE) -> TRUE | F13: Bengaluru | G13: =IF(F13=(_xlfn.XLOOKUP(RISE_lawyers!$A13, All!$A$2:$A$158,All!G$2:G$158)), TRUE, FALSE) -> TRUE | H13: Cyril Amarchand Mangaldas | J13: *Lomesh Kiran Nidumuri*
... A19: IND00589 | B19: Arbitration | C19: Rajendra Barot | D19: Senior Partner | E19: =IF(D19=(_xlfn.XLOOKUP(RISE_lawyers!$A19, All!$A$2:$A$158,All!H$2:H$158)), TRUE, FALSE) -> TRUE | F19: Mumbai | G19: =IF(F19=(_xlfn.XLOOKUP(RISE_lawyers!$A19, All!$A$2:$A$158,All!G$2:G$158)), TRUE, FALSE) -> TRUE | H19: AZB & Partners | J19: X
A20: IND00929 | B20: Arbitration | C20: Sameer Tapia | D20: Founder & Senior Partner | E20: =IF(D20=(_xlfn.XLOOKUP(RISE_lawyers!$A20, All!$A$2:$A$158,All!H$2:H$158)), TRUE, FALSE) -> TRUE | F20: Mumbai | G20: =IF(F20=(_xlfn.XLOOKUP(RISE_lawyers!$A20, All!$A$2:$A$158,All!G$2:G$158)), TRUE, FALSE) -> TRUE | H20: ALMT Legal | J20: X | K20: *Instruction Scores look off*
A21: IND00197 | B21: Arbitration | C21: Sanjeev K Kapoor | D21: Partner | E21: =IF(D21=(_xlfn.XLOOKUP(RISE_lawyers!$A21, All!$A$2:$A$158,All!H$2:H$158)), TRUE, FALSE) -> TRUE | F21: Delhi | G21: =IF(F21=(_xlfn.XLOOKUP(RISE_lawyers!$A21, All!$A$2:$A$158,All!G$2:G$158)), TRUE, FALSE) -> TRUE | H21: Khaitan & Co | J21: X
A22: IND00386 | B22: Arbitration | C22: Shaneen Parikh | D22: Partner (Head - International Arbitration) | E22: =IF(D22=(_xlfn.XLOOKUP(RISE_lawyers!$A22, All!$A$2:$A$158,All!H$2:H$158)), TRUE, FALSE) -> TRUE | F22: Mumbai | G22: =IF(F22=(_xlfn.XLOOKUP(RISE_lawyers!$A22, All!$A$2:$A$158,All!G$2:G$158)), TRUE, FALSE) -> TRUE | H22: Cyril Amarchand Mangaldas | J22: X
A23: IND00788 | B23: Arbitration | C23: Shankh Sengupta | D23: Partner | E23: =IF(D23=(_xlfn.XLOOKUP(RISE_lawyers!$A23, All!$A$2:$A$158,All!H$2:H$158)), TRUE, FALSE) -> TRUE | F23: Delhi | G23: =IF(F23=(_xlfn.XLOOKUP(RISE_lawyers!$A23, All!$A$2:$A$158,All!G$2:G$158)), TRUE, FALSE) -> TRUE | H23: Trilegal | J23: *Partner & Head of Dispute Practice*
A24: IND00540 | B24: Arbitration | C24: Smarika Singh | D24: Partner | E24: =IF(D24=(_xlfn.XLOOKUP(RISE_lawyers!$A24, All!$A$2:$A$158,All!H$2:H$158)), TRUE, FALSE) -> TRUE | F24: Delhi | G24: =IF(F24=(_xlfn.XLOOKUP(RISE_lawyers!$A24, All!$A$2:$A$158,All!G$2:G$158)), TRUE, FALSE) -> TRUE | H24: Shardul Amarchand Mangaldas & Co | J24: X
A25: IND01048 | B25: Arbitration | C25: Sneha Jaisingh | D25: Partner | E25: =IF(D25=(_xlfn.XLOOKUP(RISE_lawyers!$A25, All!$A$2:$A$158,All!H$2:H$158)), TRUE, FALSE) -> TRUE | F25: Mumbai | G25: =IF(F25=(_xlfn.XLOOKUP(RISE_lawyers!$A25, All!$A$2:$A$158,All!G$2:G$158)), TRUE, FALSE) -> TRUE | H25: Bharucha & Partners | J25: *Partner and Practice Lead*
A26: IND07574 | B26: Arbitration | C26: Sooraj Sharma | D26: Partner | E26: =IF(D26=(_xlfn.XLOOKUP(RISE_lawyers!$A26, All!$A$2:$A$158,All!H$2:H$158)), TRUE, FALSE) -> TRUE | F26: Delhi | G26: =IF(F26=(_xlfn.XLOOKUP(RISE_lawyers!$A26, All!$A$2:$A$158,All!G$2:G$158)), TRUE, FALSE) -> TRUE | H26: Clavius Legal | J26: *Founding Partner*
A27: IND02569 | B27: Arbitration | C27: Suvigya Awasthy | D27: Partner | E27: =IF(D27=(_xlfn.XLOOKUP(RISE_lawyers!$A27, All!$A$2:$A$158,All!H$2:H$158)), TRUE, FALSE) -> TRUE | F27: Delhi | G27: =IF(F27=(_xlfn.XLOOKUP(RISE_lawyers!$A27, All!$A$2:$A$158,All!G$2:G$158)), TRUE, FALSE) -> TRUE | H27: PSL Advocates & Solicitors | J27: X
A28: IND00801 | B28: Arbitration | C28: Tine Abraham | D28: Partner | E28: =IF(D28=(_xlfn.XLOOKUP(RISE_lawyers!$A28, All!$A$2:$A$158,All!H$2:H$158)), TRUE, FALSE) -> TRUE | F28: Delhi | G28: =IF(F28=(_xlfn.XLOOKUP(RISE_lawyers!$A28, All!$A$2:$A$158,All!G$2:G$158)), TRUE, FALSE) -> TRUE | H28: Trilegal | J28: X
A29: IND00602 | B29: Arbitration | C29: Vijayendra Pratap Singh | D29: Senior Partner | E29: =IF(D29=(_xlfn.XLOOKUP(RISE_lawyers!$A29, All!$A$2:$A$158,All!H$2:H$158)), TRUE, FALSE) -> TRUE | F29: Delhi | G29: =IF(F29=(_xlfn.XLOOKUP(RISE_lawyers!$A29, All!$A$2:$A$158,All!G$2:G$158)), TRUE, FALSE) -> TRUE | H29: AZB & Partners | J29: X
A30: IND02504 | B30: Arbitration | C30: Vyapak Desai | D30: Counsel | E30: =IF(D30=(_xlfn.XLOOKUP(RISE_lawyers!$A30, All!$A$2:$A$158,All!H$2:H$158)), TRUE, FALSE) -> TRUE | F30: Mumbai | G30: =IF(F30=(_xlfn.XLOOKUP(RISE_lawyers!$A30, All!$A$2:$A$158,All!G$2:G$158)), TRUE, FALSE) -> TRUE | H30: Vyapak Desai Law Chambers | J30: X
A31: IND02631 | B31: Arbitration | C31: Gunita Pahwa | D31: Joint Managing Partner | E31: =IF(D31=(_xlfn.XLOOKUP(RISE_lawyers!$A31, All!$A$2:$A$158,All!H$2:H$158)), TRUE, FALSE) -> TRUE | F31: Delhi | G31: =IF(F31=(_xlfn.XLOOKUP(RISE_lawyers!$A31, All!$A$2:$A$158,All!G$2:G$158)), TRUE, FALSE) -> TRUE | H31: S&A Law Offices | J31: *Delhi*
A32: IND02534 | B32: Capital Markets - Debt | C32: Aditya Bhargava | D32: Partner | E32: =IF(D32=(_xlfn.XLOOKUP(RISE_lawyers!$A32, All!$A$2:$A$158,All!H$2:H$158)), TRUE, FALSE) -> TRUE | F32: Mumbai | G32: =IF(F32=(_xlfn.XLOOKUP(RISE_lawyers!$A32, All!$A$2:$A$158,All!G$2:G$158)), TRUE, FALSE) -> TRUE | H32: Trilegal | J32: X
... A121: IND01511 | B121: Competition; International Trade | C121: Parthsarathi Jha | D121: Partner | E121: =IF(D121=(_xlfn.XLOOKUP(RISE_lawyers!$A121, All!$A$2:$A$158,All!H$2:H$158)), TRUE, FALSE) -> TRUE | F121: Delhi | G121: =IF(F121=(_xlfn.XLOOKUP(RISE_lawyers!$A121, All!$A$2:$A$158,All!G$2:G$158)), TRUE, FALSE) -> TRUE | H121: Economic Laws Practice | J121: X
A122: IND05097 | B122: Cyber | C122: Aadya Misra | D122: Counsel | E122: =IF(D122=(_xlfn.XLOOKUP(RISE_lawyers!$A122, All!$A$2:$A$158,All!H$2:H$158)), TRUE, FALSE) -> TRUE | F122: Bengaluru | G122: =IF(F122=(_xlfn.XLOOKUP(RISE_lawyers!$A122, All!$A$2:$A$158,All!G$2:G$158)), TRUE, FALSE) -> TRUE | H122: Spice Route Legal
A123: IND04874 | B123: Cyber | C123: Akash Karmakar | D123: Partner | E123: =IF(D123=(_xlfn.XLOOKUP(RISE_lawyers!$A123, All!$A$2:$A$158,All!H$2:H$158)), TRUE, FALSE) -> TRUE | F123: Delhi | G123: =IF(F123=(_xlfn.XLOOKUP(RISE_lawyers!$A123, All!$A$2:$A$158,All!G$2:G$158)), TRUE, FALSE) -> TRUE | H123: Panag & Babu
A124: IND00291 | B124: Cyber | C124: Anirban Mohapatra | D124: Partner | E124: =IF(D124=(_xlfn.XLOOKUP(RISE_lawyers!$A124, All!$A$2:$A$158,All!H$2:H$158)), TRUE, FALSE) -> TRUE | F124: Bengaluru | G124: =IF(F124=(_xlfn.XLOOKUP(RISE_lawyers!$A124, All!$A$2:$A$158,All!G$2:G$158)), TRUE, FALSE) -> TRUE | H124: Cyril Amarchand Mangaldas
A125: IND00298 | B125: Cyber | C125: Arun Prabhu | D125: Partner (Co-head - Technology & Telecommunications) | E125: =IF(D125=(_xlfn.XLOOKUP(RISE_lawyers!$A125, All!$A$2:$A$158,All!H$2:H$158)), TRUE, FALSE) -> TRUE | F125: Bengaluru | G125: =IF(F125=(_xlfn.XLOOKUP(RISE_lawyers!$A125, All!$A$2:$A$158,All!G$2:G$158)), TRUE, FALSE) -> TRUE | H125: Cyril Amarchand Mangaldas | J125: *Arun S. Prabhu*
A126: IND00095 | B126: Cyber | C126: Harsh Walia | D126: Partner | E126: =IF(D126=(_xlfn.XLOOKUP(RISE_lawyers!$A126, All!$A$2:$A$158,All!H$2:H$158)), TRUE, FALSE) -> TRUE | F126: Delhi | G126: =IF(F126=(_xlfn.XLOOKUP(RISE_lawyers!$A126, All!$A$2:$A$158,All!G$2:G$158)), TRUE, FALSE) -> TRUE | H126: Khaitan & Co
A127: IND00455 | B127: Cyber | C127: Hemant Krishna | D127: Partner | E127: =IF(D127=(_xlfn.XLOOKUP(RISE_lawyers!$A127, All!$A$2:$A$158,All!H$2:H$158)), TRUE, FALSE) -> TRUE | F127: Bengaluru | G127: =IF(F127=(_xlfn.XLOOKUP(RISE_lawyers!$A127, All!$A$2:$A$158,All!G$2:G$158)), TRUE, FALSE) -> TRUE | H127: Shardul Amarchand Mangaldas & Co
A128: IND00732 | B128: Cyber | C128: Jaideep Reddy | D128: Partner | E128: =IF(D128=(_xlfn.XLOOKUP(RISE_lawyers!$A128, All!$A$2:$A$158,All!H$2:H$158)), TRUE, FALSE) -> TRUE | F128: Bengaluru | G128: =IF(F128=(_xlfn.XLOOKUP(RISE_lawyers!$A128, All!$A$2:$A$158,All!G$2:G$158)), TRUE, FALSE) -> TRUE | H128: Trilegal
A129: IND00734 | B129: Cyber | C129: Jyotsna Jayaram | D129: Partner | E129: =IF(D129=(_xlfn.XLOOKUP(RISE_lawyers!$A129, All!$A$2:$A$158,All!H$2:H$158)), TRUE, FALSE) -> TRUE | F129: Bengaluru | G129: =IF(F129=(_xlfn.XLOOKUP(RISE_lawyers!$A129, All!$A$2:$A$158,All!G$2:G$158)), TRUE, FALSE) -> TRUE | H129: Trilegal
A130: IND03226 | B130: Cyber | C130: Mathew Chacko | D130: Founding Partner | E130: =IF(D130=(_xlfn.XLOOKUP(RISE_lawyers!$A130, All!$A$2:$A$158,All!H$2:H$158)), TRUE, FALSE) -> TRUE | F130: Bengaluru | G130: =IF(F130=(_xlfn.XLOOKUP(RISE_lawyers!$A130, All!$A$2:$A$158,All!G$2:G$158)), TRUE, FALSE) -> TRUE | H130: Spice Route Legal
A131: IND01738 | B131: Cyber | C131: Namita Viswanath | D131: Partner | E131: =IF(D131=(_xlfn.XLOOKUP(RISE_lawyers!$A131, All!$A$2:$A$158,All!H$2:H$158)), TRUE, FALSE) -> TRUE | F131: Bengaluru | G131: =IF(F131=(_xlfn.XLOOKUP(RISE_lawyers!$A131, All!$A$2:$A$158,All!G$2:G$158)), TRUE, FALSE) -> TRUE | H131: CMS INDUSLAW
A132: IND07527 | B132: Cyber | C132: Nehaa Chaudhari | D132: Partner | E132: =IF(D132=(_xlfn.XLOOKUP(RISE_lawyers!$A132, All!$A$2:$A$158,All!H$2:H$158)), TRUE, FALSE) -> TRUE | F132: Bengaluru | G132: =IF(F132=(_xlfn.XLOOKUP(RISE_lawyers!$A132, All!$A$2:$A$158,All!G$2:G$158)), TRUE, FALSE) -> TRUE | H132: Ikigai Law
A133: IND00757 | B133: Cyber | C133: Nikhil Narendran | D133: Partner | E133: =IF(D133=(_xlfn.XLOOKUP(RISE_lawyers!$A133, All!$A$2:$A$158,All!H$2:H$158)), TRUE, FALSE) -> TRUE | F133: Bengaluru | G133: =IF(F133=(_xlfn.XLOOKUP(RISE_lawyers!$A133, All!$A$2:$A$158,All!G$2:G$158)), TRUE, FALSE) -> TRUE | H133: Trilegal
...

Sheet All
A1: Resight ID | B1: New Resight ID | C1: Ranking | D1: @Image path | E1: Name | F1: Bio | G1: Location | H1: Position | I1: Organisation | J1: Total | K1: Badge | L1: Rank | M1: Reputation score | N1: Reputation score Median | O1: Reputation rank badge | P1: R Peers | Q1: R Peers Median | R1: R Directories | S1: R Directories Median | T1: R News media | U1: R News media Median | V1: R Social media | W1: R Social media Median | X1: Instructions score | Y1: Instructions score Median | Z1: Instructions rank badge | AA1: I Volume | AB1: I Volume Median | AC1: I Value | AD1: I Value Median | AE1: I Clients | AF1: I Clients Median | AG1: I Complexity | AH1: I Complexity Median | AI1: Sophistication score | AJ1: Sophistication score Median | AK1: Sophistication rank badge | AL1: S Tech and data | AM1: S Tech and data Median | AN1: S Pricing | AO1: S Pricing Median | AP1: S Talent development | AQ1: S Talent development Median | AR1: Experience score | AS1: Experience score Median | AT1: Experience rank badge | AU1: E Service | AV1: E Service Median | AW1: E Expertise | AX1: E Expertise Median | AY1: E Commerciality | AZ1: E Commerciality Median | BA1: E Communication | BB1: E Communication Median | BC1: E EQ | BD1: E EQ Median | BE1: E Strategy | BF1: E Strategy Median | BG1: E Network | BH1: E Network Median | BI1: E Leadership | BJ1: E Leadership Median
A2: IND05097 | B2: IND05097 | C2: Cyber | D2: Aadya-Misra.webp | E2: Aadya Misra | F2: Aadya Misra receives an excellent RISE client experience score, with a number of client recommendations and particularly high ratings for service, commerciality and EQ (emotional quotient and ability to empathise and walk in the client's shoes). Misra is also included in the list on the basis of a strong RISE instruction score. Misra has a purely data protection and cyber focused practice, one of the few in this cohort that does not sit within a broader TMT or corporate department. Her clients include domestic Indian companies expanding into the EU, Southeast Asia, the Middle East, and the US, where cross-border data transfer and localisation requirements drive most of the complexity. Her work includes data governance structures, cybersecurity, and data architecture compliance across Indian and foreign jurisdictions. Misra also makes use of a client-facing data hub offering compliance tools and an interactive comparative map of data and cyber laws, reflected in her sophistication of practice RISE score. Her EnRoute programme offers 100 hours of free legal service to small companies and also provides a structured training ground for junior lawyers building advisory confidence under supervision. | G2: Bengaluru | H2: Counsel | I2: Spice Route Legal | J2: 5.3 | L2: 16 | M2: 3.3 | N2: 3.75 | P2: 0 | Q2: 0 | R2: 6 | S2: 7.1 | T2: 8.5 | U2: 8 | V2: 8.3 | W2: 8.3 | X2: 7.1 | Y2: 8 | AA2: 7.8 | AB2: 7.6 | AC2: - | AD2: 0 | AE2: 4.8 | AF2: 8.8 | AG2: 8 | AH2: 7.5 | AI2: 5.7 | AJ2: 6.7 | AL2: 3.3 | AM2: 6.7 | AN2: 6 | AO2: 7 | AP2: 8 | AQ2: 6 | AR2: 9.8 | AS2: 8.5 | AT2: Ranked 1st | AU2: 10 | AV2: 10 | AW2: 9.6 | AX2: 10 | AY2: 10 | AZ2: 10 | BA2: 9.6 | BB2: 10 | BC2: 10 | BD2: 10 | BE2: 9.6 | BF2: 10 | BG2: 9.6 | BH2: 10 | BI2: 9.6 | BJ2: 10
A3: IND06252 | B3: IND06252 | C3: Capital Markets - Equity | D3: Photos/Aashima-Johur.png | E3: Aashima Johur | F3: Aashima Johur at Cyril Amarchand Mangaldas has built her practice around new-age, technology-focused, asset-light companies, working almost exclusively as issuer counsel, a positioning that gives her deeper insight into non-traditional capital structures, employee incentive schemes, and promoter arrangements than a bank-side practice typically produces. Instruction scores are her strongest RISE metric, but she also scores well on some sophistication sub-indicators such as pricing flexibility, and she switches between fixed fees and hourly rates in ways appropriate to client and matter. For pre-IPO advisory work—where the firm entrenches itself with potential issuers up to a year before the formal process begins to assess IPO readiness and identify areas requiring "cleaning up"—the firm tends to work on an hourly basis. Johur also scores strongly on the complexity of her mandates in line with her focus on new age companies. Her matters have received a lot of media attention. For example, the Lenskart IPO generated significant social media discussion about valuation and promoter incentives, requiring the team to address public perception and justify the commercial arrangements. | G3: Delhi | H3: Partner | I3: Cyril Amarchand Mangaldas | J3: 5.7 | L3: 24 | M3: 2.4 | N3: 4.9 | P3: 0 | Q3: 3.2 | R3: 2.9 | S3: 6 | T3: 6.7 | U3: 6.8 | V3: 8.4 | W3: 8.5 | X3: 8.1 | Y3: 8.2 | AA3: 7.4 | AB3: 7.3 | AC3: 8.6 | AD3: 8.6 | AE3: 6.3 | AF3: 9.4 | AG3: 8.8 | AH3: 8.2 | AI3: 7.7 | AJ3: 7.1 | AK3: Top 10 | AL3: 7.3 | AM3: 7.3 | AN3: 8 | AO3: 7 | AP3: 8 | AQ3: 8 | AR3: 8.5 | AS3: 8.5 | AU3: 10 | AV3: 10 | AW3: 10 | AX3: 10 | AY3: 10 | AZ3: 10 | BA3: 10 | BB3: 10 | BC3: 10 | BD3: 10 | BE3: 10 | BF3: 10 | BG3: 10 | BH3: 10 | BI3: 10 | BJ3: 10
A4: IND00004 | B4: IND00004 | C4: Capital Markets - Equity | D4: Photos/Ayush Mohata - ECM.png | E4: Aayush Mohata | F4: Aayush Mohata combines strong AI and sophistication scores with a deliberate focus on quality over quantity, building a practice around fewer and larger mandates rather than volume. He uses the firm's KAI platform across a wide range of tasks including preparing diligence checklists, benchmarking disclosures against recent regulatory precedents, and identifying consent triggers in financing documents. Mohata also invests heavily in structured training, running tailored, annual programmes for junior lawyers and bespoke sessions for new joiners. One of his most prominent recent matters is Knowledge Realty Trust’s IPO, India's largest REIT and Asia's second largest, sponsored by Blackstone alongside Sattva Developers. | G4: Mumbai | H4: Partner | I4: Khaitan & Co | J4: 4.2 | L4: 39 | M4: 2.4 | N4: 4.9 | P4: 0 | Q4: 3.2 | R4: 2.9 | S4: 6 | T4: 6.2 | U4: 6.8 | V4: 9 | W4: 8.5 | X4: 4 | Y4: 8.2 | AA4: 6.7 | AB4: 7.3 | AC4: 0 | AD4: 8.6 | AE4: 4.7 | AF4: 9.4 | AG4: 6.5 | AH4: 8.2 | AI4: 8.3 | AJ4: 7.1 | AK4: Top 5 | AL4: 8.7 | AM4: 7.3 | AN4: 8 | AO4: 7 | AP4: 8 | AQ4: 8 | AR4: 8.3 | AS4: 8.5 | AU4: 10 | AV4: 10 | AW4: 10 | AX4: 10 | AY4: 10 | AZ4: 10 | BA4: 10 | BB4: 10 | BC4: 10 | BD4: 10 | BE4: 8 | BF4: 10 | BG4: 10 | BH4: 10 | BI4: 10 | BJ4: 10
A5: IND01474 | B5: IND01474 | C5: Competition | D5: Photos/Mr-Abhay-Joshi.jpg | E5: Abhay Joshi | F5: Abhay Joshi’s strongest RISE metric is Instructions, driven by the exceptional complexity of mandates he handles for a high-quality client roster. His portfolio includes IREL India, Bridgestone India, SKF India, Ecozen Solutions, Corteva Agriscience, and United Breweries. His practice is defined by these layered enforcement matters rather than routine market-share analysis, reflecting a deep institutional understanding of Indian competition law. Joshi differentiates himself through his "quiet achiever" status; while his Reputation score is more minimal, his work on sophisticated regulatory intersections is notable. He recently defended IREL in a monopoly abuse case, arguing that strategic policy context justifies market position. His work for United Breweries involved navigating a highly regulated industry to address complex business issues regarding the sharing of commercially sensitive pricing and production data. Having transitioned from a background in M&A and private equity, Joshi also leverages a growing strand of data privacy work. He believes this forward-facing approach, treating privacy as a non-price parameter in competition analysis, is essential for modern market power mandates. | G5: Delhi | H5: Partner | I5: Economic Laws Practice | J5: 5.2 | L5: 38 | M5: 2.8 | N5: 5.6 | P5: 0 | Q5: 4.1 | R5: 7.1 | S5: 7.5 | T5: 3.6 | U5: 5.9 | V5: 8.4 | W5: 8.3 | X5: 7.5 | Y5: 8.4 | AA5: 4.8 | AB5: 7.4 | AC5: - | AD5: 0 | AE5: 8.2 | AF5: 9.5 | AG5: 8.5 | AH5: 8.5 | AI5: 5.5 | AJ5: 6.7 | AL5: 5.3 | AM5: 6.7 | AN5: 5 | AO5: 7 | AP5: 6 | AQ5: 7.5 | AR5: - | AS5: 8.5 | AU5: - | AV5: 10 | AW5: - | AX5: 10 | AY5: - | AZ5: 10 | BA5: - | BB5: 10 | BC5: - | BD5: 10 | BE5: - | BF5: 10 | BG5: - | BH5: 10 | BI5: - | BJ5: 10
A6: IND00005 | B6: IND00005 | C6: Capital Markets - Equity | D6: Photos/Abhimanyu-Bhattacharya.png | E6: Abhimanyu Bhattacharya | F6: Abhimanyu Bhattacharya works across the full public markets ecosystem, advising financial sponsors on IPO exits and issuers on listings, with clients including Apollo Global, Blackstone, TPG, and SoftBank. His highest RISE score is for the reputation indicator, where he draws solid peer recommendations, and a visible presence legal directory presence. His mandates consistently involve sponsor-heavy transactions with large, complex cap tables. Meesho's IPO is a good example: a reverse-flipped issuer with a novel business model where the core challenge was aligning numerous financial sponsors and renegotiating pre-IPO documentation to get the transaction ready for market. | G6: Mumbai | H6: Partner | I6: Khaitan & Co | J6: 7.9 | K6: Top 10 | L6: 8 | M6: 8 | N6: 4.9 | O6: Top 10 | P6: 7.7 | Q6: 3.2 | R6: 9.3 | S6: 6 | T6: 7 | U6: 6.8 | V6: 8.5 | W6: 8.5 | X6: 7.9 | Y6: 8.2 | AA6: 6.1 | AB6: 7.3 | AC6: 8.5 | AD6: 8.6 | AE6: 6.5 | AF6: 9.4 | AG6: 8.5 | AH6: 8.2 | AI6: 7.5 | AJ6: 7.1 | AK6: Top 10 | AL6: 7.3 | AM6: 7.3 | AN6: 7 | AO6: 7 | AP6: 8 | AQ6: 8 | AR6: - | AS6: 8.5 | AU6: - | AV6: 10 | AW6: - | AX6: 10 | AY6: - | AZ6: 10 | BA6: - | BB6: 10 | BC6: - | BD6: 10 | BE6: - | BF6: 10 | BG6: - | BH6: 10 | BI6: - | BJ6: 10
A7: IND03708 | B7: IND03708 | C7: Capital Markets - Equity | D7: Photos/Abhinav Maver - ECM.png | E7: Abhinav Maker | F7: Abhinav Maker's instruction and sophistication scores at Trilegal are underpinned by a practice that treats regulatory engagement as a client service rather than a compliance obligation. Maker works directly with SEBI on consultation papers and uses client interviews to shape how his team tracks and communicates regulatory change. AI and data usage is a strong sub-indicator. Maker also prioritises training for his team, which includes mandatory biweekly sessions and knowledge sharing to keep the team current. He has worked on some novel transactions such as the Bluestone IPO, which required creating new structural mechanisms to meet shareholding rules that a series of funding rounds had made impossible to satisfy in the conventional way, and Dam Capital that became India's first investment bank to go public. He works in the BFSI, manufacturing, infrastructure, and new-age technology sectors. | G7: Delhi | H7: Partner | I7: Trilegal | J7: 5.7 | L7: 27 | M7: 2.3 | N7: 4.9 | P7: 0 | Q7: 3.2 | R7: 2.9 | S7: 6 | T7: 6 | U7: 6.8 | V7: 8.4 | W7: 8.5 | X7: 8.2 | Y7: 8.2 | AA7: 7.8 | AB7: 7.3 | AC7: 8 | AD7: 8.6 | AE7: 8.9 | AF7: 9.4 | AG7: 8.2 | AH7: 8.2 | AI7: 7.4 | AJ7: 7.1 | AL7: 8 | AM7: 7.3 | AN7: 7 | AO7: 7 | AP7: - | AQ7: 8 | AR7: - | AS7: 8.5 | AU7: - | AV7: 10 | AW7: - | AX7: 10 | AY7: - | AZ7: 10 | BA7: - | BB7: 10 | BC7: - | BD7: 10 | BE7: - | BF7: 10 | BG7: - | BH7: 10 | BI7: - | BJ7: 10
A8: IND00406 | B8: IND00406 | C8: Capital Markets - Equity | D8: Photos/Abhiroop-Amitava-Datta- ECM.png | E8: Abhiroop Datta | F8: Abhiroop Datta at Shardul Amarchand Mangaldas & Co scores most strongly on RISE sophistication metrics, with technology usage and talent development the standout sub-indicators. He connects Outlook to Harvey to pull and summarise all correspondence relating to a transaction, replacing manual inbox management, and stores transaction data in structured archives to run analyses without risk. His practice spans large regulated-sector IPOs and technology listings, including matters using SEBI's confidential filing route, with experience across a wide range of promoter profiles and investor types from family-led Indian businesses to international corporate and financial sponsors. He regularly advises on public regulatory compliance issues where multiple regulators or large syndicates are involved. A personal background spanning three countries and ten cities has given him an ability to engage comfortably across socio-economic and cultural contexts, from traditional Indian promoters to sophisticated international clients. | G8: Delhi | H8: Partner | I8: Shardul Amarchand Mangaldas & Co | J8: 5.3 | L8: 36 | M8: 2.4 | N8: 4.9 | P8: 0 | Q8: 3.2 | R8: 2.9 | S8: 6 | T8: 7 | U8: 6.8 | V8: 8.1 | W8: 8.5 | X8: 7 | Y8: 8.2 | AA8: 5.1 | AB8: 7.3 | AC8: 8.1 | AD8: 8.6 | AE8: 7.1 | AF8: 9.4 | AG8: 7 | AH8: 8.2 | AI8: 7.6 | AJ8: 7.1 | AK8: Top 10 | AL8: 8 | AM8: 7.3 | AN8: 6 | AO8: 7 | AP8: 8 | AQ8: 8 | AR8: - | AS8: 8.5 | AU8: - | AV8: 10 | AW8: - | AX8: 10 | AY8: - | AZ8: 10 | BA8: - | BB8: 10 | BC8: - | BD8: 10 | BE8: - | BF8: 10 | BG8: - | BH8: 10 | BI8: - | BJ8: 10
A9: IND07656 | B9: IND08613 | C9: Competition | D9: Photos/abir-roy-neww.png | E9: Abir Roy | F9: Abir Roy at Sarvada Legal occupies an unusual position in the Indian competition market: an enforcement-led practice running approximately 80% contentious work, with a distinct concentration on the complainant side in big tech platform cases at a time when most comparable complexity sits within larger full-service firms. Sophistication and Experience are also rated highly, with technology and value the standout sub-indicators within each. Abir's work on Google, Apple and app ecosystem matters involves technical arguments around platform economics, data flows and jurisdictional overlap with data protection, with data accumulation treated as a source of dominance rather than a separate regulatory question. A notable feature is his representation of app developer communities acting collectively against dominant platforms, requiring coordination of multi-party complainant strategies across long-running, multi-forum disputes. He argues his own matters and maintains full file ownership throughout, a model that suits the litigation-control and forum-strategy dimension of enforcement work but operates from a smaller platform than the full-service practices handling comparable complexity. | G9: Delhi | H9: Co-founder & Partner | I9: Sarvada Legal | J9: 6.1 | L9: 28 | M9: 5.3 | N9: 5.6 | P9: 4.1 | Q9: 4.1 | R9: 7.5 | S9: 7.5 | T9: 4.2 | U9: 5.9 | V9: 9.2 | W9: 8.3 | X9: 6.5 | Y9: 8.4 | AA9: 10 | AB9: 7.4 | AC9: - | AD9: 0 | AE9: 0 | AF9: 9.5 | AG9: 9 | AH9: 8.5 | AI9: 6.6 | AJ9: 6.7 | AL9: 6 | AM9: 6.7 | AN9: 7 | AO9: 7 | AP9: 7 | AQ9: 7.5 | AR9: - | AS9: 8.5 | AU9: - | AV9: 10 | AW9: - | AX9: 10 | AY9: - | AZ9: 10 | BA9: - | BB9: 10 | BC9: - | BD9: 10 | BE9: - | BF9: 10 | BG9: - | BH9: 10 | BI9: - | BJ9: 10
A10: IND00016 | B10: IND00016 | C10: Capital Markets - Equity | D10: Photos/Aditya Cheriyan.png | E10: Aditya George Cheriyan | F10: Aditya George Cheriyan's is a modern-day of practitioner. His highest RISE scores come under 'Sophistication' of practice, essentially in the business of law. His role in developing his team is his standout sub-indicator. His associate training covers legal expertise, financial literacy, negotiation, and client communication, Associates are assessed regularly and developed through workshops and partner-led mentoring. Cheriyan teaches externally at Gujarat National Law University, which doubles as a talent pipeline and has contributed to less attrition in his team compared to peers. Clients include Travel Food Services, Sai Life Sciences, and Meesho, each involving novel equity arrangements, regulatory challenges, or cross-border structuring. His team systematically tracks what is market across transactions even where the firm is not instructed. | G10: Mumbai | H10: Partner | I10: Khaitan & Co | J10: 7.1 | L10: 14 | M10: 5.9 | N10: 4.9 | P10: 6.2 | Q10: 3.2 | R10: 2.9 | S10: 6 | T10: 7.6 | U10: 6.8 | V10: 8.3 | W10: 8.5 | X10: 7.5 | Y10: 8.2 | AA10: 6.7 | AB10: 7.3 | AC10: 8.2 | AD10: 8.6 | AE10: 6.8 | AF10: 9.4 | AG10: 7.8 | AH10: 8.2 | AI10: 8.6 | AJ10: 7.1 | AK10: Ranked 2nd | AL10: 8 | AM10: 7.3 | AN10: 7 | AO10: 7 | AP10: 10 | AQ10: 8 | AR10: 7.8 | AS10: 8.5 | AU10: 10 | AV10: 10 | AW10: 10 | AX10: 10 | AY10: 8 | AZ10: 10 | BA10: 10 | BB10: 10 | BC10: 6 | BD10: 10 | BE10: 8 | BF10: 10 | BG10: 10 | BH10: 10 | BI10: 10 | BJ10: 10
A11: IND00020 | B11: IND00020 | C11: Arbitration | D11: Photos/Ajay Bhargava_0.png | E11: Ajay Bhargava | F11: Ajay Bhargava runs a high-volume practice for Indian conglomerates, multinationals, and government bodies, with instructions from Aditya Birla Group, Adani Group, L&T, Siemens, Hyundai, Panacea and INOX. Complexity is among his strongest RISE indicators, with matters regularly involving multiple jurisdictions, public sector counterparties, and points of law with no settled precedent. A standout recent matter is Antrix Corporation, the first case in India to establish a doctrine of fraud in arbitration, with enforcement proceedings running in parallel across the Netherlands, Germany, France, and the US. His RISE sophistication score is anchored in talent development, working directly on matters alongside junior lawyers and having mentored around 15 lawyers to partnership over his career. | G11: Delhi | H11: Partner | I11: Khaitan & Co | J11: 6.8 | K11: Top 10 | L11: 10 | M11: 5.1 | N11: 3.6 | P11: 3.1 | Q11: 1 | R11: 7.5 | S11: 7.1 | T11: 6.4 | U11: 6.3 | V11: 9.8 | W11: 8.9 | X11: 8.3 | Y11: 7.8 | Z11: Top 10 | AA11: 9.5 | AB11: 7.6 | AC11: 7.6 | AD11: 7.5 | AE11: 7.4 | AF11: 7.4 | AG11: 8.7 | AH11: 8.7 | AI11: 7.2 | AJ11: 7.1 | AL11: 6 | AM11: 6.7 | AN11: 6 | AO11: 6 | AP11: 9 | AQ11: 7.5 | AR11: - | AS11: 8.3 | AU11: - | AV11: 10 | AW11: - | AX11: 10 | AY11: - | AZ11: 10 | BA11: - | BB11: 10 | BC11: - | BD11: 10 | BE11: - | BF11: 10 | BG11: - | BH11: 10 | BI11: - | BJ11: 10
A12: IND02646 | B12: IND02646 | C12: International Trade | D12: Photos/Ajinkya Gunjan Mishra.jpg | E12: Ajinkya Gunjan Mishra | F12: Ajinkya Gunjan Mishra carries some of the highest news and social media scores in this cohort, writing throughout 2025 on topics including the effects of US tariffs and opportunities for India's defence sector. His instruction record in the same year includes a rare disputed benefits case under the India-Japan CEPA, one of India's most active trade corridors in Asia-Pacific. Appearances for Mishra relating to trade remedies are largely concentrated in Indian forums across all levels, including the Supreme Court, primarily for multinationals, whom he also acts for on an advisory basis. An MBA from the Indian Institute of Foreign Trade, taken thirteen years ago when that combination was uncommon for a mid-career trade lawyer, signals a commercial orientation that has shaped how he has approached mandates since. | G12: Delhi | H12: Partner | I12: S&R Associates | J12: 5.3 | L12: 15 | M12: 2.4 | N12: 3.35 | P12: 0 | Q12: 0 | R12: 0 | S12: 7.1 | T12: 9.4 | U12: 7.1 | V12: 10 | W12: 8.9 | X12: 7.6 | Y12: 8.6 | AA12: 8.6 | AB12: 8.6 | AC12: - | AD12: 0 | AE12: 8.3 | AF12: 8.9 | AG12: 7 | AH12: 8.7 | AI12: 6.5 | AJ12: 6.4 | AK12: Top 10 | AL12: 6.7 | AM12: 5.3 | AN12: 7 | AO12: 7 | AP12: 6 | AQ12: 7.5 | AR12: 8.5 | AS12: 8.3 | AT12: Top 10 | AU12: 10 | AV12: 10 | AW12: 10 | AX12: 10 | AY12: 10 | AZ12: 10 | BA12: 10 | BB12: 10 | BC12: 10 | BD12: 10 | BE12: 10 | BF12: 10 | BG12: 10 | BH12: 10 | BI12: 10 | BJ12: 10
A13: IND02656 | B13: IND02656 | C13: Competition | D13: Photos/Akshat-Kulshrestha-GS.jpg | E13: Akshat Kulshrestha | F13: Akshat Kulshrestha at S&R Associates scores most strongly on RISE instruction metrics, driven by technically demanding merger control work and growing enforcement exposure rather than filing volume alone. His Client base is the standout sub-indicator, spanning infrastructure, private equity, and logistics, alongside cartel defence and High Court litigation for a top global express courier company. RISE sophistication scores are the second strongest signal. AI usage is notable, with the team building a competition-specific repository of CCI precedents segmented by conduct type, penalty range, and market definition using Lucio. | G13: Delhi | H13: Partner | I13: S&R Associates | J13: 5.1 | L13: 40 | M13: 2.3 | N13: 5.6 | P13: 0 | Q13: 4.1 | R13: 5.8 | S13: 7.5 | T13: 2.6 | U13: 5.9 | V13: 7.5 | W13: 8.3 | X13: 7.2 | Y13: 8.4 | AA13: 5.3 | AB13: 7.4 | AC13: - | AD13: 0 | AE13: 9.2 | AF13: 9.5 | AG13: 7 | AH13: 8.5 | AI13: 6.7 | AJ13: 6.7 | AL13: 6.7 | AM13: 6.7 | AN13: 8 | AO13: 7 | AP13: 6 | AQ13: 7.5 | AR13: - | AS13: 8.5 | AU13: - | AV13: 10 | AW13: - | AX13: 10 | AY13: - | AZ13: 10 | BA13: - | BB13: 10 | BC13: - | BD13: 10 | BE13: - | BF13: 10 | BG13: - | BH13: 10 | BI13: - | BJ13: 10
A14: IND00698 | B14: IND00698 | C14: Capital Markets - Equity | D14: Photos/Albin-Thomas-1.png | E14: Albin Thomas | F14: Albin Thomas's instruction scores are his strongest RISE metric, built on a practice that spans both ECM and DCM and a track record of first-of-their-kind transactions that generates repeat work. The Mahindra Finance rights issue, one of the first executed under the new streamlined SEBI regime, and the ROADIS high-yield bond, the first tollway high-yield bond in India, are good illustrations of his work. Thomas' AI and data usage is the sophistication standout: his team captures SEBI observations on filed offer documents into a structured database, creating ready-made prompts for drafting teams on what the regulator has been scrutinising in the past six months. Clients include Mahindra Group, IIFL Capital, and Jefferies. | G14: Mumbai | H14: Partner | I14: Trilegal | J14: 5.9 | L14: 23 | M14: 2.4 | N14: 4.9 | P14: 0 | Q14: 3.2 | R14: 2.9 | S14: 6 | T14: 6.2 | U14: 6.8 | V14: 9.5 | W14: 8.5 | X14: 8.8 | Y14: 8.2 | Z14: Top 10 | AA14: 8.4 | AB14: 7.3 | AC14: 8.6 | AD14: 8.6 | AE14: 9.9 | AF14: 9.4 | AG14: 8.5 | AH14: 8.2 | AI14: 7.1 | AJ14: 7.1 | AL14: 8.7 | AM14: 7.3 | AN14: 6 | AO14: 7 | AP14: 6 | AQ14: 8 | AR14: - | AS14: 8.5 | AU14: - | AV14: 10 | AW14: - | AX14: 10 | AY14: - | AZ14: 10 | BA14: - | BB14: 10 | BC14: - | BD14: 10 | BE14: - | BF14: 10 | BG14: - | BH14: 10 | BI14: - | BJ14: 10
A15: IND00291 | B15: IND00291 | C15: Cyber | D15: Anirban Mohapatra.jpg | E15: Anirban Mohapatra | F15: Anirban Mohapatra receives a high RISE client experience score. Clients rated his service, commerciality, EQ and network particularly highly. Mohapatra's score on the RISE instruction metric reflects a cross-sector practice spanning large technology companies, domestic and global banks, insurance companies, and platforms. His cyber advisory practice sits within the firm's new Digital Plus practice, a unified team that covers transactions, advisory, and incident response for clients. A strong score on the RISE sophistication metric is also is based on an advanced use of technology and approach to talent development. Mohapatra's training philosophy requires junior lawyers to understand technology architecture before advising on it. The firm uses legal AI tool Legora, and his team has built a proprietary prompt library refined in weekly sessions, with AI now deployed on transaction checklists, drafting, summarisation, and first-response analysis across data-heavy matters. He also authored a public cybersecurity handbook drawing on global precedent and client experience. | G15: Bengaluru | H15: Partner | I15: Cyril Amarchand Mangaldas | J15: 5.3 | L15: 17 | M15: 2 | N15: 3.75 | P15: 0 | Q15: 0 | R15: 6 | S15: 7.1 | T15: 0 | U15: 8 | V15: 7.9 | W15: 8.3 | X15: 7.6 | Y15: 8 | AA15: 6.5 | AB15: 7.6 | AC15: - | AD15: 0 | AE15: 8.9 | AF15: 8.8 | AG15: 7.5 | AH15: 7.5 | AI15: 7.4 | AJ15: 6.7 | AK15: Top 5 | AL15: 8 | AM15: 6.7 | AN15: 7 | AO15: 7 | AP15: 7 | AQ15: 6 | AR15: 9 | AS15: 8.5 | AT15: Top 5 | AU15: 10 | AV15: 10 | AW15: 9 | AX15: 10 | AY15: 10 | AZ15: 10 | BA15: 9 | BB15: 10 | BC15: 10 | BD15: 10 | BE15: 8 | BF15: 10 | BG15: 10 | BH15: 10 | BI15: 9 | BJ15: 10
A16: IND02193 | B16: IND02193 | C16: International Trade | D16: Photos/Ankur Sharma.jpg | E16: Ankur Sharma | F16: Ankur Sharma at Lakshmikumaran & Sridharan has established a leading position in sanctions and carbon border adjustment mechanism advisory, two of the fastest-moving sub-practice areas in international trade, at a moment when most practitioners are still developing their footing in both. Sharma scores in the top 5 for the RISE instructions metric as a result of his expertise in these frontier specialisms. Sharma's talent development for junior lawyers is also strong, with training structured around emerging laws paired with business development strategy. A background in engineering rather than the accountancy qualifications more common among trade lawyers gives him a mathematical foundation that he applies directly to the economic analysis that CBAM work demands. | G16: Delhi | H16: Partner | I16: Lakshmikumaran & Sridharan | J16: 6.2 | K16: Top 10 | L16: 10 | M16: 3.3 | N16: 3.35 | O16: Top 10 | P16: 0 | Q16: 0 | R16: 7.1 | S16: 7.1 | T16: 6.5 | U16: 7.1 | V16: 8.8 | W16: 8.9 | X16: 9.2 | Y16: 8.6 | Z16: Top 5 | AA16: 8.4 | AB16: 8.6 | AC16: - | AD16: 0 | AE16: 9.6 | AF16: 8.9 | AG16: 9.3 | AH16: 8.7 | AI16: 6 | AJ16: 6.4 | AL16: 4 | AM16: 5.3 | AN16: 6 | AO16: 7 | AP16: 8 | AQ16: 7.5 | AR16: 6.8 | AS16: 8.3 | AU16: 6 | AV16: 10 | AW16: 8 | AX16: 10 | AY16: 8 | AZ16: 10 | BA16: 8 | BB16: 10 | BC16: 8 | BD16: 10 | BE16: 8 | BF16: 10 | BG16: 8 | BH16: 10 | BI16: 8 | BJ16: 10
A17: IND00038 | B17: IND00038 | C17: Competition | D17: Photos/Anshuman Sakle 2025 web_0.png | E17: Anshuman Sakle | F17: Anshuman Sakle ranks eighth in the RISE competition standings, supported by a near-equal balance between his reputation and instruction scores. His reputation is defined by exceptional visibility; he is one of the most frequently quoted practitioners in the legal press and maintains an excellent profile across international legal directories and peer mentions. His Instructions score is equally robust, reflecting a high-volume, high-complexity practice that handled 17 major transactions in 2025 for a prestigious client roster including Torrent Pharmaceuticals, Mahindra & Mahindra, Haldiram Snack Foods, Interpublic Group (IPG), Wilmar International, and American Axle & Manufacturing. Based in Mumbai, Sakle’s practice typically splits 75% toward merger control and 25% toward enforcement, though he notes this ratio fluctuates with the Commission’s investigative cycles. He differentiates himself through a culture of team continuity; by giving associates early client-facing responsibility, he maintains notably low attrition rates. This stability, combined with his long-standing engagement with the CCI, provides clients with reliable regulatory navigation across diverse sectors such as pharma, financial services, and oil and gas. His profile marks him as a highly visible market leader who remains deeply embedded in the execution of complex, sector-spanning mandates. | G17: Mumbai | H17: Partner | I17: Khaitan & Co | J17: 7.9 | K17: Top 10 | L17: 8 | M17: 8.1 | N17: 5.6 | O17: Top 10 | P17: 6.9 | Q17: 4.1 | R17: 9.2 | S17: 7.5 | T17: 10 | U17: 5.9 | V17: 9.3 | W17: 8.3 | X17: 8.3 | Y17: 8.4 | AA17: 7.5 | AB17: 7.4 | AC17: - | AD17: 0 | AE17: 9.4 | AF17: 9.5 | AG17: 8 | AH17: 8.5 | AI17: 6.9 | AJ17: 6.7 | AL17: 6.7 | AM17: 6.7 | AN17: 7 | AO17: 7 | AP17: 7 | AQ17: 7.5 | AR17: 8.5 | AS17: 8.5 | AT17: Top 10 | AU17: 10 | AV17: 10 | AW17: 10 | AX17: 10 | AY17: 10 | AZ17: 10 | BA17: 10 | BB17: 10 | BC17: 10 | BD17: 10 | BE17: 10 | BF17: 10 | BG17: 10 | BH17: 10 | BI17: 10 | BJ17: 10
A18: IND00968 | B18: IND00968 | C18: Competition | D18: Photos/Anu Monga.jpg | E18: Anu Monga | F18: Anu Monga achieves the second-highest experience score in her cohort, rated particularly strongly by clients for her expertise, commerciality, and communication. Instruction scores are her second strongest RISE metric, driven by advisory work for multiple Indian ministries on policy and by representing the Government of India before foreign authorities including in the US, Canada and China. She co-leads the youngest firm in this ranking of top international trade lawyers, formed only in 2020. Perhaps partly from the agility of being a smaller, younger firm, AnantLaw is the only Indian firm using the global legal research platform VLex. It is also a signal of the practice's orientation toward international standards. Complementary specialisations across international trade, competition law, and disputes, combined with deep government advisory work, produce a practice that is as politically attuned as it is technically grounded. | G18: Delhi | H18: Partner | I18: AnantLaw | J18: 5.7 | L18: 32 | M18: 2.7 | N18: 5.6 | P18: 0 | Q18: 4.1 | R18: 5.1 | S18: 7.5 | T18: 5.9 | U18: 5.9 | V18: 7.7 | W18: 8.3 | X18: 8.9 | Y18: 8.4 | AA18: 6.4 | AB18: 7.4 | AC18: - | AD18: 0 | AE18: 6.6 | AF18: 9.5 | AG18: 10 | AH18: 8.5 | AI18: 5.4 | AJ18: 6.7 | AL18: 4 | AM18: 6.7 | AN18: 7 | AO18: 7 | AP18: 6 | AQ18: 7.5 | AR18: 9 | AS18: 8.5 | AT18: Top 10 | AU18: 9 | AV18: 10 | AW18: 10 | AX18: 10 | AY18: 10 | AZ18: 10 | BA18: 10 | BB18: 10 | BC18: 9 | BD18: 10 | BE18: 9 | BF18: 10 | BG18: 9 | BH18: 10 | BI18: 9 | BJ18: 10
A19: IND00968 | B19: IND00968 | C19: International Trade | D19: Photos/Anu Monga.jpg | E19: Anu Monga | F19: Anu Monga achieves the second-highest experience score in her cohort, rated particularly strongly by clients for her expertise, commerciality, and communication. Instruction scores are her second strongest RISE metric, driven by advisory work for multiple Indian ministries on policy and by representing the Government of India before foreign authorities including in the US, Canada and China. She co-leads the youngest firm in this ranking of top international trade lawyers, formed only in 2020. Perhaps partly from the agility of being a smaller, younger firm, AnantLaw is the only Indian firm using the global legal research platform VLex. It is also a signal of the practice's orientation toward international standards. Complementary specialisations across international trade, competition law, and disputes, combined with deep government advisory work, produce a practice that is as politically attuned as it is technically grounded. | G19: Delhi | H19: Partner | I19: AnantLaw | J19: 5.3 | L19: 13 | M19: 2.1 | N19: 3.35 | P19: 0 | Q19: 0 | R19: 0 | S19: 7.1 | T19: 8 | U19: 7.1 | V19: 8.7 | W19: 8.9 | X19: 8.6 | Y19: 8.6 | Z19: Top 10 | AA19: 8.6 | AB19: 8.6 | AC19: - | AD19: 0 | AE19: 8.7 | AF19: 8.9 | AG19: 8.5 | AH19: 8.7 | AI19: 5.4 | AJ19: 6.4 | AL19: 4 | AM19: 5.3 | AN19: 7 | AO19: 7 | AP19: 6 | AQ19: 7.5 | AR19: 9 | AS19: 8.3 | AT19: Ranked 2nd | AU19: 9 | AV19: 10 | AW19: 10 | AX19: 10 | AY19: 10 | AZ19: 10 | BA19: 10 | BB19: 10 | BC19: 9 | BD19: 10 | BE19: 9 | BF19: 10 | BG19: 9 | BH19: 10 | BI19: 9 | BJ19: 10
A20: IND07570 | B20: IND08621 | C20: International Trade | D20: Photos/Anuradha R V.jpg | E20: Anuradha RV | F20: Anuradha RV at Clarus Law Associates has built a practice on policy and high-level advisory rather than the anti-dumping foundation more common for a trade lawyer. Her work is focused more on services and sustainability commitments as well as investment commitments in bilateral investment treaties, and her clientele includes government bodies and industry associations. She consults with the International Trade Center in Geneva, supporting countries on trade policy development and WTO accession, a mandate profile that operates at a different level of the market to most practitioners here. She is a prolific writer and teacher alongside her practice, co-authoring articles with economists on India's trade policies for publications including the Hindustan Times and Mint, a combination that reinforces both her external profile and technical proficiency in emerging sub-practice areas of trade law. Talent development is a strong sub-indicator, with associates rotated across trade, investment, and policy to broaden exposure and match availability to workflow. | G20: Delhi | H20: Partner | I20: Clarus Law Associates | J20: 6.1 | K20: Top 10 | L20: 9 | M20: 3.4 | N20: 3.35 | O20: Top 10 | P20: 0 | Q20: 0 | R20: 7.5 | S20: 7.1 | T20: 10 | U20: 7.1 | V20: 9.1 | W20: 8.9 | X20: 8.9 | Y20: 8.6 | Z20: Top 10 | AA20: 8.9 | AB20: 8.6 | AC20: - | AD20: 0 | AE20: 9 | AF20: 8.9 | AG20: 8.8 | AH20: 8.7 | AI20: 6 | AJ20: 6.4 | AK20: Top 10 | AL20: 2.7 | AM20: 5.3 | AN20: - | AO20: 7 | AP20: 9 | AQ20: 7.5 | AR20: - | AS20: 8.3 | AU20: - | AV20: 10 | AW20: - | AX20: 10 | AY20: - | AZ20: 10 | BA20: - | BB20: 10 | BC20: - | BD20: 10 | BE20: - | BF20: 10 | BG20: - | BH20: 10 | BI20: - | BJ20: 10
A21: IND00428 | B21: IND00428 | C21: Competition | D21: Photos/Aparna Mehra.png | E21: Aparna Mehra | F21: Aparna Mehra ranks within the top 20 of the RISE Competition list, with her strongest metric being Reputation. This standing is driven by consistent recognition across legal directories and a notable social media presence, alongside a solid profile among her peers. Her Instructions score is also robust; while she maintains an understated profile, she remains a trusted advisor for high-caliber clients including ArcelorMittal, Bain Capital Investors, Jindal Steel & Power, Rolls-Royce India, and Vedanta Limited. As one of the first generation of Indian competition specialists with two decades of experience, Mehra’s practice has a distinct cross-border character. She is frequently sought out as local counsel by firms in Japan, Brussels, London, and New York for specialist mandates. She believes her practice is valued for its reliability and deep system-level understanding of Indian merger control. This expertise is evident in her analysis of deal value thresholds and evolving green channel filing behaviors, reflecting a sophisticated grasp of the regulatory landscape that transcends individual mandates. | G21: Delhi | H21: Partner | I21: Trilegal | J21: 7 | L21: 18 | M21: 7.5 | N21: 5.6 | O21: Top 10 | P21: 7.2 | Q21: 4.1 | R21: 7.8 | S21: 7.5 | T21: 7.5 | U21: 5.9 | V21: 8.3 | W21: 8.3 | X21: 6.8 | Y21: 8.4 | AA21: 7.2 | AB21: 7.4 | AC21: - | AD21: 0 | AE21: 7.6 | AF21: 9.5 | AG21: 6 | AH21: 8.5 | AI21: 6.5 | AJ21: 6.7 | AL21: - | AM21: 6.7 | AN21: 6 | AO21: 7 | AP21: - | AQ21: 7.5 | AR21: - | AS21: 8.5 | AU21: - | AV21: 10 | AW21: - | AX21: 10 | AY21: - | AZ21: 10 | BA21: - | BB21: 10 | BC21: - | BD21: 10 | BE21: - | BF21: 10 | BG21: - | BH21: 10 | BI21: - | BJ21: 10
A22: IND01915 | B22: IND01915 | C22: Capital Markets - Equity | D22: Photos/Arka-Mookerjee-Profile-Picture.jpg | E22: Arka Mookerjee | F22: Around 90 per cent of Arka Mookerjee's work at J. Sagar Associates is independently generated, a figure that is unusual at his level and reflected by his instruction scores in the RISE rating. His client roster spans Temasek, for whom he handles all Indian exits, alongside Axis, Kotak, Citi, and JPMorgan. A significant portion of his practice covers government infrastructure mandates. The Raajmarg Infra Investment Trust, the first government-sponsored InvIT in the roads sector, required an entirely new structure to monetise completed road assets outside a standard disinvestment framework, a transaction that illustrates both the complexity and the novelty of his practice. | G22: Mumbai | H22: Partner | I22: JSA Advocates & Solicitors | J22: 7.4 | L22: 11 | M22: 6.5 | N22: 4.9 | P22: 4.5 | Q22: 3.2 | R22: 9 | S22: 6 | T22: 8.5 | U22: 6.8 | V22: 9.3 | W22: 8.5 | X22: 9 | Y22: 8.2 | Z22: Top 10 | AA22: 9.2 | AB22: 7.3 | AC22: 9 | AD22: 8.6 | AE22: 9.9 | AF22: 9.4 | AG22: 8.5 | AH22: 8.2 | AI22: 6.2 | AJ22: 7.1 | AL22: 4 | AM22: 7.3 | AN22: 7 | AO22: 7 | AP22: 8 | AQ22: 8 | AR22: 7.9 | AS22: 8.5 | AU22: 10 | AV22: 10 | AW22: 10 | AX22: 10 | AY22: 10 | AZ22: 10 | BA22: 8 | BB22: 10 | BC22: 10 | BD22: 10 | BE22: 8 | BF22: 10 | BG22: 8 | BH22: 10 | BI22: 10 | BJ22: 10
A23: IND00298 | B23: IND00298 | C23: Cyber | D23: Arun-S.-Prabhu-1.png | E23: Arun Prabhu | F23: Arun Prabhu has developed a leading cyber practice at the firm over the past two decades, and is frequently quoted in the press as a thought leader on data protection and technology law and policy. This is shown in his leading score for the RISE news media metric, and strong overall reputation rating. He acts for many global tech giants, but his transactional and advisory work cuts across sectors as organisations look to implement new compliance measures to meet India's new data protection requirements. A high score on the RISE instructions metrics draws on a profile client bases as well as handling a large number , and high complexity of cyber matters in the past year. Prabhu is closely engaged with the Indian regulators and helps client anticipate changes in India's rapidly changing regulatory environment. Amongst the tech-savvy cyber practitioners, he also scores highly on the RISE sophistication metrics. He uses a range of AI tools for document review, red teaming, and client-specific tasks, and to help more accurately predict client fees. | G23: Bengaluru | H23: Partner (Co-Head - Technology & Telecommunications) | I23: Cyril Amarchand Mangaldas | J23: 7.2 | K23: Top 5 | L23: 5 | M23: 7.2 | N23: 3.75 | O23: Top 5 | P23: 6 | Q23: 0 | R23: 7.5 | S23: 7.1 | T23: 10 | U23: 8 | V23: 8.5 | W23: 8.3 | X23: 7.5 | Y23: 8 | AA23: 8 | AB23: 7.6 | AC23: - | AD23: 0 | AE23: 8.2 | AF23: 8.8 | AG23: 7 | AH23: 7.5 | AI23: 6.8 | AJ23: 6.7 | AK23: Top 10 | AL23: 8 | AM23: 6.7 | AN23: 10 | AO23: 7 | AP23: 4 | AQ23: 6 | AR23: - | AS23: 8.5 | AU23: - | AV23: 10 | AW23: - | AX23: 10 | AY23: - | AZ23: 10 | BA23: - | BB23: 10 | BC23: - | BD23: 10 | BE23: - | BF23: 10 | BG23: - | BH23: 10 | BI23: - | BJ23: 10
A24: IND07515 | B24: IND08609 | C24: Arbitration | D24: Photos/Ashim Sood.jpg | E24: Ashim Sood | F24: Ashim Sood runs a deliberately constrained practice built around depth rather than volume, concentrating on a small number of matters at a time. Direct senior involvement is the product rather than an occasional feature. His RISE instruction scores reflect this: the work he takes on is typically complex in legal rather than financial terms, gravitating toward jurisdictional questions, corporate veil arguments, and cases where the applicable framework is genuinely unsettled. His sophistication score is anchored in how he deploys technology. He uses AI primarily as a verification layer to identify contradictions across documents and cross-check witness statements against correspondence, and is building a knowledge management system to retrieve prior research systematically across matters. | G24: Delhi | H24: Principal | I24: Ashim Sood Law Offices | J24: 5.2 | L24: 28 | M24: 2.8 | N24: 3.6 | P24: 1 | Q24: 1 | R24: 6.6 | S24: 7.1 | T24: 0 | U24: 6.3 | V24: 9.2 | W24: 8.9 | X24: 7.7 | Y24: 7.8 | AA24: 7.1 | AB24: 7.6 | AC24: 9.1 | AD24: 7.5 | AE24: 7.1 | AF24: 7.4 | AG24: 7.3 | AH24: 8.7 | AI24: 5.2 | AJ24: 7.1 | AL24: 6 | AM24: 6.7 | AN24: 6 | AO24: 6 | AP24: 4 | AQ24: 7.5 | AR24: - | AS24: 8.3 | AU24: - | AV24: 10 | AW24: - | AX24: 10 | AY24: - | AZ24: 10 | BA24: - | BB24: 10 | BC24: - | BD24: 10 | BE24: - | BF24: 10 | BG24: - | BH24: 10 | BI24: - | BJ24: 10
A25: IND00712 | B25: IND00712 | C25: Arbitration | D25: Photos/ashish-bhan.png | E25: Ashish Bhan | F25: Ashish Bhan has been at Trilegal since 2010 and leads a team of 25 to 30 lawyers, with arbitration accounting for around 45 to 50% of his personal practice. AI usage drives his strong RISE sophistication score. Running searches across Trilegal's 25-year database via Lucio, his team recently identified eight recurring risk areas in a defence tender in days rather than the two days of manual file review previously required. Defence and aviation manufacturers form the core of his client base, with a practice specialising in procurement arbitrations involving G2G contracts, geopolitical sensitivities, and strategic decisions about which claims to press and which to concede to preserve government relationships across jurisdictions. | G25: Delhi | H25: Partner | I25: Trilegal | J25: 5.9 | L25: 16 | M25: 3 | N25: 3.6 | P25: 1 | Q25: 1 | R25: 7.8 | S25: 7.1 | T25: 0 | U25: 6.3 | V25: 9.2 | W25: 8.9 | X25: 7.8 | Y25: 7.8 | AA25: 5.5 | AB25: 7.6 | AC25: 8.1 | AD25: 7.5 | AE25: 6.8 | AF25: 7.4 | AG25: 8.7 | AH25: 8.7 | AI25: 7.9 | AJ25: 7.1 | AK25: Ranked 1st | AL25: 9.3 | AM25: 6.7 | AN25: - | AO25: 6 | AP25: - | AQ25: 7.5 | AR25: 7.9 | AS25: 8.3 | AU25: 10 | AV25: 10 | AW25: 10 | AX25: 10 | AY25: 10 | AZ25: 10 | BA25: 8 | BB25: 10 | BC25: 10 | BD25: 10 | BE25: 8 | BF25: 10 | BG25: 8 | BH25: 10 | BI25: 10 | BJ25: 10
A26: IND01267 | B26: IND01267 | C26: International Trade | D26: Photos/Ashish-Chandra.jpg | E26: Ashish Chandra | F26: Ashish Chandra at DSK Legal is one of a small number of Indian trade lawyers with direct WTO litigation experience, and with the appellate system now near non-functioning, he has redirected that expertise into trade disputes before domestic high courts. This, in part, earns him a place in the top 10 of scores for the RISE instructions metric. Additionally to WTO and trade disputes, Chandra is involved in trade remedies, customs, export controls and sanctions. He advised the Government of Korea until 2024 in Indian trade remedy investigations, a mandate that sits alongside a full-service trade practice spanning the complete range of matters. | G26: Delhi | H26: Partner | I26: DSK Legal | J26: 5.8 | L26: 11 | M26: 3.2 | N26: 3.35 | P26: 0 | Q26: 0 | R26: 8.7 | S26: 7.1 | T26: 3.8 | U26: 7.1 | V26: 8.9 | W26: 8.9 | X26: 8.6 | Y26: 8.6 | Z26: Top 10 | AA26: 8.8 | AB26: 8.6 | AC26: - | AD26: 0 | AE26: 8.5 | AF26: 8.9 | AG26: 8.6 | AH26: 8.7 | AI26: 5.2 | AJ26: 6.4 | AL26: 4 | AM26: 5.3 | AN26: 4 | AO26: 7 | AP26: 7 | AQ26: 7.5 | AR26: 8.1 | AS26: 8.3 | AT26: Top 10 | AU26: 10 | AV26: 10 | AW26: 10 | AX26: 10 | AY26: 10 | AZ26: 10 | BA26: 10 | BB26: 10 | BC26: 8 | BD26: 10 | BE26: 10 | BF26: 10 | BG26: 8 | BH26: 10 | BI26: 10 | BJ26: 10
A27: IND07689 | B27: IND08618 | C27: International Trade | D27: Photos/Atul Sharma.png | E27: Atul Sharma | F27: Atul Sharma at Sarvada is the strongest-performing practitioner from a boutique in this cohort, driven by peer recommendations and a mandate profile that includes acting as lead counsel for the Government of India in active WTO disputes and representing a Saudi Arabian chemical corporation before the US Department of Commerce in third-country trade remedy proceedings unrelated to India. His score for the pricing RISE metric is the highest, underpinned by structured scoping systems and deferred payment arrangements aligned to client billing cycles, a commercial flexibility that larger firms rarely offer. A practical differentiator in his client service is working directly through clients' SAP and Oracle systems to extract and reconcile raw data for filings, reducing the burden on client teams and improving the accuracy of submissions. | G27: Delhi | H27: Partner | I27: Sarvada Legal | J27: 7.2 | K27: Top 10 | L27: 6 | M27: 6 | N27: 3.35 | O27: Top 10 | P27: 3.8 | Q27: 0 | R27: 7.5 | S27: 7.1 | T27: 9.5 | U27: 7.1 | V27: 9.3 | W27: 8.9 | X27: 9.1 | Y27: 8.6 | Z27: Top 10 | AA27: 8.2 | AB27: 8.6 | AC27: - | AD27: 0 | AE27: 9.4 | AF27: 8.9 | AG27: 9.3 | AH27: 8.7 | AI27: 5.7 | AJ27: 6.4 | AL27: 5.3 | AM27: 5.3 | AN27: 8 | AO27: 7 | AP27: 5 | AQ27: 7.5 | AR27: - | AS27: 8.3 | AU27: - | AV27: 10 | AW27: - | AX27: 10 | AY27: - | AZ27: 10 | BA27: - | BB27: 10 | BC27: - | BD27: 10 | BE27: - | BF27: 10 | BG27: - | BH27: 10 | BI27: - | BJ27: 10
A28: IND00301 | B28: IND00301 | C28: Competition | D28: Photos/avantika kakkar.jpg | E28: Avaantika Kakkar | F28: Avaantika Kakkar’s strongest RISE metrics are Reputation and Instructions, with high scores driven by consistent peer recognition, strong directory presence and sustained demand from sophisticated clients. Her practice spans the Commission, appellate forums, High Courts and the Supreme Court, a breadth of forum coverage within a single practice that differentiates her in a market where many competition partners operate more narrowly. She is focused on complex, data-heavy merger control work across healthcare, infrastructure and industrial sectors, where market definition and competitive effects are actively contested. She operates a lean staffing model, giving associates and partners greater ownership of matters. On the enforcement side, she has been involved in a number of the regulator’s most significant dawn raids, including instructions from clients outside the firm’s existing base, reflecting trust in high-pressure situations. | G28: Mumbai | H28: Partner (Head - Competition Law) | I28: Cyril Amarchand Mangaldas | J28: 8.7 | K28: Ranked 3rd | L28: 3 | M28: 9 | N28: 5.6 | O28: Ranked 3rd | P28: 8.7 | Q28: 4.1 | R28: 10 | S28: 7.5 | T28: 8.7 | U28: 5.9 | V28: 9.1 | W28: 8.3 | X28: 9.2 | Y28: 8.4 | Z28: Top 5 | AA28: 8.9 | AB28: 7.4 | AC28: - | AD28: 0 | AE28: 9.9 | AF28: 9.5 | AG28: 9 | AH28: 8.5 | AI28: 7.2 | AJ28: 6.7 | AL28: 6 | AM28: 6.7 | AN28: 8 | AO28: 7 | AP28: 8 | AQ28: 7.5 | AR28: 9.1 | AS28: 8.5 | AT28: Top 10 | AU28: 10 | AV28: 10 | AW28: 10 | AX28: 10 | AY28: 10 | AZ28: 10 | BA28: 9 | BB28: 10 | BC28: 10 | BD28: 10 | BE28: 10 | BF28: 10 | BG28: 8 | BH28: 10 | BI28: 9 | BJ28: 10
